Workbook

Sheet Месячные данные
A1: Год | B1: Месяц | C1: Импорт, т | D1: Импорт, тыс. долл. США | E1: Экспорт, т | F1: Экспорт, тыс. долл. США | H1: Месяц | I1: Импорт | J1: Экспорт
A2: 2008 | B2: Январь | C2: =IF('Годовые данные'!$B$2="","",'Годовые данные'!$B$2*$I$2) -> 40.1399 | D2: =IF('Годовые данные'!$C$2="","",'Годовые данные'!$C$2*$I$2) -> 7.455 | E2: =IF('Годовые данные'!$D$2="","",'Годовые данные'!$D$2*$J$2) -> 0.01606 | F2: =IF('Годовые данные'!$E$2="","",'Годовые данные'!$E$2*$J$2) -> 0.005 | H2: Январь | I2: 0.01 | J2: 0.005
A3: 2008 | B3: Февраль | C3: =IF('Годовые данные'!$B$2="","",'Годовые данные'!$B$2*$I$3) -> 40.1399 | D3: =IF('Годовые данные'!$C$2="","",'Годовые данные'!$C$2*$I$3) -> 7.455 | E3: =IF('Годовые данные'!$D$2="","",'Годовые данные'!$D$2*$J$3) -> 0.01606 | F3: =IF('Годовые данные'!$E$2="","",'Годовые данные'!$E$2*$J$3) -> 0.005 | H3: Февраль | I3: 0.01 | J3: 0.005
A4: 2008 | B4: Март | C4: =IF('Годовые данные'!$B$2="","",'Годовые данные'!$B$2*$I$4) -> 80.2798 | D4: =IF('Годовые данные'!$C$2="","",'Годовые данные'!$C$2*$I$4) -> 14.91 | E4: =IF('Годовые данные'!$D$2="","",'Годовые данные'!$D$2*$J$4) -> 0.03212 | F4: =IF('Годовые данные'!$E$2="","",'Годовые данные'!$E$2*$J$4) -> 0.01 | H4: Март | I4: 0.02 | J4: 0.01
A5: 2008 | B5: Апрель | C5: =IF('Годовые данные'!$B$2="","",'Годовые данные'!$B$2*$I$5) -> 160.5596 | D5: =IF('Годовые данные'!$C$2="","",'Годовые данные'!$C$2*$I$5) -> 29.82 | E5: =IF('Годовые данные'!$D$2="","",'Годовые данные'!$D$2*$J$5) -> 0.03212 | F5: =IF('Годовые данные'!$E$2="","",'Годовые данные'!$E$2*$J$5) -> 0.01 | H5: Апрель | I5: 0.04 | J5: 0.01
A6: 2008 | B6: Май | C6: =IF('Годовые данные'!$B$2="","",'Годовые данные'!$B$2*$I$6) -> 401.399 | D6: =IF('Годовые данные'!$C$2="","",'Годовые данные'!$C$2*$I$6) -> 74.55 | E6: =IF('Годовые данные'!$D$2="","",'Годовые данные'!$D$2*$J$6) -> 0.06424 | F6: =IF('Годовые данные'!$E$2="","",'Годовые данные'!$E$2*$J$6) -> 0.02 | H6: Май | I6: 0.1 | J6: 0.02
A7: 2008 | B7: Июнь | C7: =IF('Годовые данные'!$B$2="","",'Годовые данные'!$B$2*$I$7) -> 722.5182 | D7: =IF('Годовые данные'!$C$2="","",'Годовые данные'!$C$2*$I$7) -> 134.19 | E7: =IF('Годовые данные'!$D$2="","",'Годовые данные'!$D$2*$J$7) -> 0.12848 | F7: =IF('Годовые данные'!$E$2="","",'Годовые данные'!$E$2*$J$7) -> 0.04 | H7: Июнь | I7: 0.18 | J7: 0.04
A8: 2008 | B8: Июль | C8: =IF('Годовые данные'!$B$2="","",'Годовые данные'!$B$2*$I$8) -> 883.0778 | D8: =IF('Годовые данные'!$C$2="","",'Годовые данные'!$C$2*$I$8) -> 164.01 | E8: =IF('Годовые данные'!$D$2="","",'Годовые данные'!$D$2*$J$8) -> 0.38544 | F8: =IF('Годовые данные'!$E$2="","",'Годовые данные'!$E$2*$J$8) -> 0.12 | H8: Июль | I8: 0.22 | J8: 0.12
A9: 2008 | B9: Август | C9: =IF('Годовые данные'!$B$2="","",'Годовые данные'!$B$2*$I$9) -> 762.6581 | D9: =IF('Годовые данные'!$C$2="","",'Годовые данные'!$C$2*$I$9) -> 141.645 | E9: =IF('Годовые данные'!$D$2="","",'Годовые данные'!$D$2*$J$9) -> 0.83512 | F9: =IF('Годовые данные'!$E$2="","",'Годовые данные'!$E$2*$J$9) -> 0.26 | H9: Август | I9: 0.19 | J9: 0.26
A10: 2008 | B10: Сентябрь | C10: =IF('Годовые данные'!$B$2="","",'Годовые данные'!$B$2*$I$10) -> 521.8187 | D10: =IF('Годовые данные'!$C$2="","",'Годовые данные'!$C$2*$I$10) -> 96.915 | E10: =IF('Годовые данные'!$D$2="","",'Годовые данные'!$D$2*$J$10) -> 0.803 | F10: =IF('Годовые данные'!$E$2="","",'Годовые данные'!$E$2*$J$10) -> 0.25 | H10: Сентябрь | I10: 0.13 | J10: 0.25
A11: 2008 | B11: Октябрь | C11: =IF('Годовые данные'!$B$2="","",'Годовые данные'!$B$2*$I$11) -> 240.8394 | D11: =IF('Годовые данные'!$C$2="","",'Годовые данные'!$C$2*$I$11) -> 44.73 | E11: =IF('Годовые данные'!$D$2="","",'Годовые данные'!$D$2*$J$11) -> 0.4818 | F11: =IF('Годовые данные'!$E$2="","",'Годовые данные'!$E$2*$J$11) -> 0.15 | H11: Октябрь | I11: 0.06 | J11: 0.15
A12: 2008 | B12: Ноябрь | C12: =IF('Годовые данные'!$B$2="","",'Годовые данные'!$B$2*$I$12) -> 120.4197 | D12: =IF('Годовые данные'!$C$2="","",'Годовые данные'!$C$2*$I$12) -> 22.365 | E12: =IF('Годовые данные'!$D$2="","",'Годовые данные'!$D$2*$J$12) -> 0.25696 | F12: =IF('Годовые данные'!$E$2="","",'Годовые данные'!$E$2*$J$12) -> 0.08 | H12: Ноябрь | I12: 0.03 | J12: 0.08
A13: 2008 | B13: Декабрь | C13: =IF('Годовые данные'!$B$2="","",'Годовые данные'!$B$2*$I$13) -> 40.1399 | D13: =IF('Годовые данные'!$C$2="","",'Годовые данные'!$C$2*$I$13) -> 7.455 | E13: =IF('Годовые данные'!$D$2="","",'Годовые данные'!$D$2*$J$13) -> 0.1606 | F13: =IF('Годовые данные'!$E$2="","",'Годовые данные'!$E$2*$J$13) -> 0.05 | H13: Декабрь | I13: 0.01 | J13: 0.05
A14: 2009 | B14: Январь | C14: =IF('Годовые данные'!$B$3="","",'Годовые данные'!$B$3*$I$2) -> 75.92 | D14: =IF('Годовые данные'!$C$3="","",'Годовые данные'!$C$3*$I$2) -> 15.157 | E14: =IF('Годовые данные'!$D$3="","",'Годовые данные'!$D$3*$J$2) -> 0.65 | F14: =IF('Годовые данные'!$E$3="","",'Годовые данные'!$E$3*$J$2) -> 0.047 | H14: Сумма долей | I14: =SUM(I2:I13) -> 1 | J14: =SUM(J2:J13) -> 1
A15: 2009 | B15: Февраль | C15: =IF('Годовые данные'!$B$3="","",'Годовые данные'!$B$3*$I$3) -> 75.92 | D15: =IF('Годовые данные'!$C$3="","",'Годовые данные'!$C$3*$I$3) -> 15.157 | E15: =IF('Годовые данные'!$D$3="","",'Годовые данные'!$D$3*$J$3) -> 0.65 | F15: =IF('Годовые данные'!$E$3="","",'Годовые данные'!$E$3*$J$3) -> 0.047
A16: 2009 | B16: Март | C16: =IF('Годовые данные'!$B$3="","",'Годовые данные'!$B$3*$I$4) -> 151.84 | D16: =IF('Годовые данные'!$C$3="","",'Годовые данные'!$C$3*$I$4) -> 30.314 | E16: =IF('Годовые данные'!$D$3="","",'Годовые данные'!$D$3*$J$4) -> 1.3 | F16: =IF('Годовые данные'!$E$3="","",'Годовые данные'!$E$3*$J$4) -> 0.094
A17: 2009 | B17: Апрель | C17: =IF('Годовые данные'!$B$3="","",'Годовые данные'!$B$3*$I$5) -> 303.68 | D17: =IF('Годовые данные'!$C$3="","",'Годовые данные'!$C$3*$I$5) -> 60.628 | E17: =IF('Годовые данные'!$D$3="","",'Годовые данные'!$D$3*$J$5) -> 1.3 | F17: =IF('Годовые данные'!$E$3="","",'Годовые данные'!$E$3*$J$5) -> 0.094
A18: 2009 | B18: Май | C18: =IF('Годовые данные'!$B$3="","",'Годовые данные'!$B$3*$I$6) -> 759.2 | D18: =IF('Годовые данные'!$C$3="","",'Годовые данные'!$C$3*$I$6) -> 151.57 | E18: =IF('Годовые данные'!$D$3="","",'Годовые данные'!$D$3*$J$6) -> 2.6 | F18: =IF('Годовые данные'!$E$3="","",'Годовые данные'!$E$3*$J$6) -> 0.188
A19: 2009 | B19: Июнь | C19: =IF('Годовые данные'!$B$3="","",'Годовые данные'!$B$3*$I$7) -> 1366.56 | D19: =IF('Годовые данные'!$C$3="","",'Годовые данные'!$C$3*$I$7) -> 272.826 | E19: =IF('Годовые данные'!$D$3="","",'Годовые данные'!$D$3*$J$7) -> 5.2 | F19: =IF('Годовые данные'!$E$3="","",'Годовые данные'!$E$3*$J$7) -> 0.376
A20: 2009 | B20: Июль | C20: =IF('Годовые данные'!$B$3="","",'Годовые данные'!$B$3*$I$8) -> 1670.24 | D20: =IF('Годовые данные'!$C$3="","",'Годовые данные'!$C$3*$I$8) -> 333.454 | E20: =IF('Годовые данные'!$D$3="","",'Годовые данные'!$D$3*$J$8) -> 15.6 | F20: =IF('Годовые данные'!$E$3="","",'Годовые данные'!$E$3*$J$8) -> 1.128
A21: 2009 | B21: Август | C21: =IF('Годовые данные'!$B$3="","",'Годовые данные'!$B$3*$I$9) -> 1442.48 | D21: =IF('Годовые данные'!$C$3="","",'Годовые данные'!$C$3*$I$9) -> 287.983 | E21: =IF('Годовые данные'!$D$3="","",'Годовые данные'!$D$3*$J$9) -> 33.8 | F21: =IF('Годовые данные'!$E$3="","",'Годовые данные'!$E$3*$J$9) -> 2.444
A22: 2009 | B22: Сентябрь | C22: =IF('Годовые данные'!$B$3="","",'Годовые данные'!$B$3*$I$10) -> 986.96 | D22: =IF('Годовые данные'!$C$3="","",'Годовые данные'!$C$3*$I$10) -> 197.041 | E22: =IF('Годовые данные'!$D$3="","",'Годовые данные'!$D$3*$J$10) -> 32.5 | F22: =IF('Годовые данные'!$E$3="","",'Годовые данные'!$E$3*$J$10) -> 2.35
A23: 2009 | B23: Октябрь | C23: =IF('Годовые данные'!$B$3="","",'Годовые данные'!$B$3*$I$11) -> 455.52 | D23: =IF('Годовые данные'!$C$3="","",'Годовые данные'!$C$3*$I$11) -> 90.942 | E23: =IF('Годовые данные'!$D$3="","",'Годовые данные'!$D$3*$J$11) -> 19.5 | F23: =IF('Годовые данные'!$E$3="","",'Годовые данные'!$E$3*$J$11) -> 1.41
A24: 2009 | B24: Ноябрь | C24: =IF('Годовые данные'!$B$3="","",'Годовые данные'!$B$3*$I$12) -> 227.76 | D24: =IF('Годовые данные'!$C$3="","",'Годовые данные'!$C$3*$I$12) -> 45.471 | E24: =IF('Годовые данные'!$D$3="","",'Годовые данные'!$D$3*$J$12) -> 10.4 | F24: =IF('Годовые данные'!$E$3="","",'Годовые данные'!$E$3*$J$12) -> 0.752
A25: 2009 | B25: Декабрь | C25: =IF('Годовые данные'!$B$3="","",'Годовые данные'!$B$3*$I$13) -> 75.92 | D25: =IF('Годовые данные'!$C$3="","",'Годовые данные'!$C$3*$I$13) -> 15.157 | E25: =IF('Годовые данные'!$D$3="","",'Годовые данные'!$D$3*$J$13) -> 6.5 | F25: =IF('Годовые данные'!$E$3="","",'Годовые данные'!$E$3*$J$13) -> 0.47
A26: 2010 | B26: Январь | C26: =IF('Годовые данные'!$B$4="","",'Годовые данные'!$B$4*$I$2) -> 194.39 | D26: =IF('Годовые данные'!$C$4="","",'Годовые данные'!$C$4*$I$2) -> 30.454 | E26: =IF('Годовые данные'!$D$4="","",'Годовые данные'!$D$4*$J$2) -> 0.54709333 | F26: =IF('Годовые данные'!$E$4="","",'Годовые данные'!$E$4*$J$2) -> 0.075666667
A27: 2010 | B27: Февраль | C27: =IF('Годовые данные'!$B$4="","",'Годовые данные'!$B$4*$I$3) -> 194.39 | D27: =IF('Годовые данные'!$C$4="","",'Годовые данные'!$C$4*$I$3) -> 30.454 | E27: =IF('Годовые данные'!$D$4="","",'Годовые данные'!$D$4*$J$3) -> 0.54709333 | F27: =IF('Годовые данные'!$E$4="","",'Годовые данные'!$E$4*$J$3) -> 0.075666667
A28: 2010 | B28: Март | C28: =IF('Годовые данные'!$B$4="","",'Годовые данные'!$B$4*$I$4) -> 388.78 | D28: =IF('Годовые данные'!$C$4="","",'Годовые данные'!$C$4*$I$4) -> 60.908 | E28: =IF('Годовые данные'!$D$4="","",'Годовые данные'!$D$4*$J$4) -> 1.0941867 | F28: =IF('Годовые данные'!$E$4="","",'Годовые данные'!$E$4*$J$4) -> 0.15133333
A29: 2010 | B29: Апрель | C29: =IF('Годовые данные'!$B$4="","",'Годовые данные'!$B$4*$I$5) -> 777.56 | D29: =IF('Годовые данные'!$C$4="","",'Годовые данные'!$C$4*$I$5) -> 121.816 | E29: =IF('Годовые данные'!$D$4="","",'Годовые данные'!$D$4*$J$5) -> 1.0941867 | F29: =IF('Годовые данные'!$E$4="","",'Годовые данные'!$E$4*$J$5) -> 0.15133333
A30: 2010 | B30: Май | C30: =IF('Годовые данные'!$B$4="","",'Годовые данные'!$B$4*$I$6) -> 1943.9 | D30: =IF('Годовые данные'!$C$4="","",'Годовые данные'!$C$4*$I$6) -> 304.54 | E30: =IF('Годовые данные'!$D$4="","",'Годовые данные'!$D$4*$J$6) -> 2.1883733 | F30: =IF('Годовые данные'!$E$4="","",'Годовые данные'!$E$4*$J$6) -> 0.30266667
A31: 2010 | B31: Июнь | C31: =IF('Годовые данные'!$B$4="","",'Годовые данные'!$B$4*$I$7) -> 3499.02 | D31: =IF('Годовые данные'!$C$4="","",'Годовые данные'!$C$4*$I$7) -> 548.172 | E31: =IF('Годовые данные'!$D$4="","",'Годовые данные'!$D$4*$J$7) -> 4.3767467 | F31: =IF('Годовые данные'!$E$4="","",'Годовые данные'!$E$4*$J$7) -> 0.60533333
A32: 2010 | B32: Июль | C32: =IF('Годовые данные'!$B$4="","",'Годовые данные'!$B$4*$I$8) -> 4276.58 | D32: =IF('Годовые данные'!$C$4="","",'Годовые данные'!$C$4*$I$8) -> 669.988 | E32: =IF('Годовые данные'!$D$4="","",'Годовые данные'!$D$4*$J$8) -> 13.13024 | F32: =IF('Годовые данные'!$E$4="","",'Годовые данные'!$E$4*$J$8) -> 1.816
A33: 2010 | B33: Август | C33: =IF('Годовые данные'!$B$4="","",'Годовые данные'!$B$4*$I$9) -> 3693.41 | D33: =IF('Годовые данные'!$C$4="","",'Годовые данные'!$C$4*$I$9) -> 578.626 | E33: =IF('Годовые данные'!$D$4="","",'Годовые данные'!$D$4*$J$9) -> 28.448853 | F33: =IF('Годовые данные'!$E$4="","",'Годовые данные'!$E$4*$J$9) -> 3.9346667
A34: 2010 | B34: Сентябрь | C34: =IF('Годовые данные'!$B$4="","",'Годовые данные'!$B$4*$I$10) -> 2527.07 | D34: =IF('Годовые данные'!$C$4="","",'Годовые данные'!$C$4*$I$10) -> 395.902 | E34: =IF('Годовые данные'!$D$4="","",'Годовые данные'!$D$4*$J$10) -> 27.354667 | F34: =IF('Годовые данные'!$E$4="","",'Годовые данные'!$E$4*$J$10) -> 3.7833333
A35: 2010 | B35: Октябрь | C35: =IF('Годовые данные'!$B$4="","",'Годовые данные'!$B$4*$I$11) -> 1166.34 | D35: =IF('Годовые данные'!$C$4="","",'Годовые данные'!$C$4*$I$11) -> 182.724 | E35: =IF('Годовые данные'!$D$4="","",'Годовые данные'!$D$4*$J$11) -> 16.4128 | F35: =IF('Годовые данные'!$E$4="","",'Годовые данные'!$E$4*$J$11) -> 2.27
A36: 2010 | B36: Ноябрь | C36: =IF('Годовые данные'!$B$4="","",'Годовые данные'!$B$4*$I$12) -> 583.17 | D36: =IF('Годовые данные'!$C$4="","",'Годовые данные'!$C$4*$I$12) -> 91.362 | E36: =IF('Годовые данные'!$D$4="","",'Годовые данные'!$D$4*$J$12) -> 8.7534933 | F36: =IF('Годовые данные'!$E$4="","",'Годовые данные'!$E$4*$J$12) -> 1.2106667
A37: 2010 | B37: Декабрь | C37: =IF('Годовые данные'!$B$4="","",'Годовые данные'!$B$4*$I$13) -> 194.39 | D37: =IF('Годовые данные'!$C$4="","",'Годовые данные'!$C$4*$I$13) -> 30.454 | E37: =IF('Годовые данные'!$D$4="","",'Годовые данные'!$D$4*$J$13) -> 5.4709333 | F37: =IF('Годовые данные'!$E$4="","",'Годовые данные'!$E$4*$J$13) -> 0.75666667
A38: 2011 | B38: Январь | C38: =IF('Годовые данные'!$B$5="","",'Годовые данные'!$B$5*$I$2) -> 92.52 | D38: =IF('Годовые данные'!$C$5="","",'Годовые данные'!$C$5*$I$2) -> 16.56 | E38: =IF('Годовые данные'!$D$5="","",'Годовые данные'!$D$5*$J$2) -> 0.44418667 | F38: =IF('Годовые данные'!$E$5="","",'Годовые данные'!$E$5*$J$2) -> 0.10433333
A39: 2011 | B39: Февраль | C39: =IF('Годовые данные'!$B$5="","",'Годовые данные'!$B$5*$I$3) -> 92.52 | D39: =IF('Годовые данные'!$C$5="","",'Годовые данные'!$C$5*$I$3) -> 16.56 | E39: =IF('Годовые данные'!$D$5="","",'Годовые данные'!$D$5*$J$3) -> 0.44418667 | F39: =IF('Годовые данные'!$E$5="","",'Годовые данные'!$E$5*$J$3) -> 0.10433333
A40: 2011 | B40: Март | C40: =IF('Годовые данные'!$B$5="","",'Годовые данные'!$B$5*$I$4) -> 185.04 | D40: =IF('Годовые данные'!$C$5="","",'Годовые данные'!$C$5*$I$4) -> 33.12 | E40: =IF('Годовые данные'!$D$5="","",'Годовые данные'!$D$5*$J$4) -> 0.88837333 | F40: =IF('Годовые данные'!$E$5="","",'Годовые данные'!$E$5*$J$4) -> 0.20866667
...

Sheet Годовые данные
A1: Год | B1: Импорт, т | C1: Импорт, тыс. долл. США | D1: Экспорт, т | E1: Экспорт, тыс. долл. США
A2: 2008 | B2: 4013.99 | C2: 745.5 | D2: 3.212 | E2: 1
A3: 2009 | B3: 7592 | C3: 1515.7 | D3: 130 | E3: 9.4
A4: 2010 | B4: 19439 | C4: 3045.4 | D4: =D3+(D6-D3)/3 -> 109.41867 | E4: =E3+(E6-E3)/3 -> 15.133333
A5: 2011 | B5: 9252 | C5: 1656 | D5: =D3+2*(D6-D3)/3 -> 88.837333 | E5: =E3+2*(E6-E3)/3 -> 20.866667
A6: 2012 | B6: 10353.554 | C6: 2319.1 | D6: 68.256 | E6: 26.6
A7: 2013 | B7: 15351 | C7: 3199.7 | D7: 23 | E7: 10.5
A8: 2014 | B8: 19051 | C8: 4901.1 | D8: 289 | E8: 73.2
A9: 2015 | B9: 21921 | C9: 4225.8 | D9: 512 | E9: 95.1
A10: 2016 | B10: 17916 | C10: 4522.8 | D10: 83 | E10: 14
A11: 2017 | B11: 24780 | C11: 4585 | D11: 297 | E11: 63.7
A12: 2018 | B12: 31129 | C12: 3865.1 | D12: 340 | E12: 75.4
A13: 2019 | B13: 29533 | C13: 4279.3 | D13: 59.5 | E13: 18.5
A14: 2020 | B14: 21759 | C14: 5157.3 | D14: 15.319 | E14: 5.9
A15: 2021 | B15: 25061 | C15: 6936 | D15: 13.499 | E15: 5.3
